Workbook
Name MageCalc: #REF!
Name DrkCalc: #REF!
Name HeroCalc: #REF!
Name BmCalc: #REF!
Name NlCalc: #REF!

Sheet range calculator
A1: Original by Geyforlife: https://mapleroyals.com/forum/threads/damage-calculator-all-classes.123479/
A2: Edited by Tim and Shiyui for damage formula corrections and other fixes. | G2: Stat calculator:
H3: Str: | I3: Dex: | J3: Int: | K3: Luk: | L3: Watk/Matt:
A4: For mages
A5: Weapon amp: | B5: =SWITCH($D$5,"Bishop",1,"Archmage",1.25,"-") -> - | C5: Job: | D5: DrK | G5: Weapon: | H5: 21 | L5: 139
A6: Spell amp: | B6: =SWITCH($D$5,"Bishop",1,"Archmage",1.4,"-") -> - | C6: =IF(OR($D$5="Hero",$D$5="Pally"),"Weapon:","") | E6: <- hit del to clear | G6: Shield:
C7: Skill Mastery: | D7: =SWITCH(D5,"MM",0.9,"BM",0.9,"DrK",0.8,0.6) -> 0.8 | G7: Armours:
A8: TMA: | B8: =J31+L31+E8+E10 -> 319 | C8: Attack Potion: | D8: Apple | E8: =SWITCH(D8,"None",0,"Stopper",IF(OR($D$5="Archmage",$D$5="Bishop"),0,60),"Apple",100,"Gelt",120,"Naricain's Demon Elixir",IF(OR($D$5="Archmage",$D$5="Bishop"),0,140),"Spellbound Lollipop",IF(OR($D$5="Archmage",$D$5="Bishop"),45,0),"Graham Pie",IF(OR($D$5="Archmage",$D$5="Bishop"),120,0),"Sswis Cheese",IF(OR($D$5="Archmage",$D$5="Bishop"),220,0),"Subani's Mystic Cauldron",IF(OR($D$5="Archmage",$D$5="Bishop"),200,0),0) -> 100 | G8: Helmet: | H8: 21 | I8: 40
C9: Projectile: | D9: None | E9: =switch($D$9,"None",0,"Ilbis/Hwabis",27,"Cilbis",29,"Bfury",30,"Eternal bullet",20,"Diamond/Red Arrow",4,0) -> 0 | G9: Top/Overall: | H9: 60 | I9: 8
C10: Echo: | D10: Yes | E10: =IF(D10="Yes",ROUNDDOWN(IF(OR($D$5="Archmage",$D$5="Bishop"),(J31+L31+E8)*0.04,(L31+E8+E9)*0.04),0),0) -> 12 | G10: Bottom:
C11: Weap Speed: | D11: 6 | E11: =IF(D14="Yes",IF(D11-4<2,2,D11-4),IF(D11-2<2,2,D11-2)) -> 2 | G11: Cape: | L11: 20
G12: Shoe: | L12: 20
C13: Sharp Eye: | D13: Yes | G13: Glove: | L13: 20
C14: Speed Infusion: | D14: Yes
C15: MW level: | D15: 20 | E15: =VLOOKUP(D15,'maple warrior'!$A$2:$B$32,2,TRUE) -> 1.1 | G15: Accessories:
C16: Type Effective? | D16: No | G16: Earring: | H16: 15
E17: =IF(OR($D$6="1H Axe",$D$6="2H Axe",$D$6="1H BW",$D$6="2H BW"),"Slash","") | F17: =IF(OR($D$6="1H Axe",$D$6="2H Axe",$D$6="1H BW",$D$6="2H BW"),"Stab",IF($D$5="NL","TT range","")) | G17: Eye accessory: | H17: 6 | I17: 6
C18: Range: | D18: =IF(OR($D$5="Hero",$D$5="Pally"),IF(NOT(OR($D$6="1H Sword",$D$6="2H Sword")),$F$18&"-"&$E$19,$E$18&"-"&$E$19),$E$18&"-"&$E$19) -> 14824-20434 | E18: =ROUNDDOWN(IF(OR($D$5="Archmage",$D$5="Bishop"),(($B$8*$B$8/1000+$B$8*0.6*0.9)/30+$J$31/200)*$B$6*$B$5,SWITCH($D$5,"Hero",H31*VLOOKUP($D$6,Weapons!$D$7:$E$13,2,false)*0.9*D7+I31,"Pally",H31*VLOOKUP($D$6,Weapons!$D$7:$E$13,2,false)*0.9*D7+I31,"DrK",H31*5*0.9*D7+I31,"MM",I31*3.6*0.9*D7+H31,"BM",I31*3.4*0.9*D7+H31,"NL",K31*3.6*0.9*D7+H31+I31,"Shad",K31*3.6*0.9*D7+H31+I31,"Bucc",H31*4.8*0.9*D7+I31,"Sair",I31*3.6*0.9*D7+H31,"ERROR")*(L31+E8+E9+E10)/100),0) -> 14824 | F18: =IF(OR($D$6="",$D$6="1H Sword",$D$6="2H Sword"),IF($D$5="NL",ROUNDDOWN(2.5*$K$31*($L$31+$E$8+$E$9+$E$10)/100,0),""),ROUNDDOWN((H31*VLOOKUP($D$6,Weapons!$D$7:$F$13,3,false)*0.9*D7+I31)*(L31+E8+E9+E10)/100,0)) | G18: Face accessory: | H18: 10 | I18: 5
E19: =ROUNDDOWN(IF(OR($D$5="Archmage",$D$5="Bishop"),(($B$8*$B$8/1000+$B$8)/30+$J$31/200)*$B$6*$B$5,SWITCH($D$5,"Hero",H31*VLOOKUP($D$6,Weapons!$D$7:$E$13,2,false)+I31,"Pally",H31*VLOOKUP($D$6,Weapons!$D$7:$E$13,2,false)+I31,"DrK",H31*5+I31,"MM",I31*3.6+H31,"BM",I31*3.4+H31,"NL",K31*3.6+H31+I31,"Shad",K31*3.6+H31+I31,"Bucc",H31*4.8+I31,"Sair",I31*3.6+H31,"ERROR")*(L31+E8+E9+E10)/100),0) -> 20434 | F19: =IF(OR($D$6="",$D$6="1H Sword",$D$6="2H Sword"),IF($D$5="NL",ROUNDDOWN(5*$K$31*($L$31+$E$8+$E$9+$E$10)/100,0),""),ROUNDDOWN((H31*VLOOKUP($D$6,Weapons!$D$7:$F$13,3,false)+I31)*(L31+E8+E9+E10)/100,0)) | G19: Pendant: | H19: 22 | I19: 23
C20: avg range | D20: =IF($F$17="",(E18+E19)/2,"") -> 17629 | G20: Belt: | I20: 5
G21: Medal: | L21: 3
D22: =IF($D$5="Shad","Ratio (look at ME for numbers)", "Ratio of Usage") -> Ratio of Usage | F22: No. of targets/other multiplier | G22: Ring (1): | H22: 8 | I22: 5
B23: Skill 1: | C23: Spear Crusher | D23: 1 | E23: =(D23/(D23+D24+D25)) -> 1 | F23: 1 | G23: Ring (2): | H23: 5 | I23: 5
B24: Skill 2: | C24: None/Idle | D24: 0 | E24: =(D24/(D23+D24+D25)) -> 0 | F24: 1 | G24: Ring (3): | H24: 3 | I24: 2
B25: Skill 3: | C25: None/Idle | D25: 0 | E25: =(D25/(D23+D24+D25)) -> 0 | F25: 1 | G25: Ring (4): | H25: 3 | I25: 3 | L25: 1
C27: Summon: | D27: None | F27: 1 | G27: Base stats (pre MW): | H27: 999 | I27: 23 | J27: 4 | K27: 4
H28: =ROUNDDOWN(H27*$E$15,0) -> 1098 | I28: =ROUNDDOWN(I27*$E$15,0) -> 25 | J28: =ROUNDDOWN(J27*$E$15,0) -> 4 | K28: =ROUNDDOWN(K27*$E$15,0) -> 4
C29: Nett DPS: | D29: =VLOOKUP(C23,dmg!B8:O1003,14,FALSE)*E23*F23+VLOOKUP(C24,dmg!B8:O1003,14,FALSE)*E24*F24+VLOOKUP(C25,dmg!B8:O1003,14,FALSE)*E25*F25+VLOOKUP(D27,summons!B2:F1003,4,FALSE)*F27 -> 249417.7
C30: Nett DPM: | D30: =CONCATENATE(ROUNDDOWN(D29*60/1000000,2),"m") -> 14.96m | H30: Str: | I30: Dex: | J30: Int: | K30: Luk: | L30: Watk*:
G31: Total stats (w/mw): | H31: =SUM(H4:H26,H28) -> 1272 | I31: =SUM(I4:I26,I28) -> 127 | J31: =SUM(J4:J26,J28) -> 4 | K31: =SUM(K4:K26,K28) -> 4 | L31: =SWITCH($D$5,"MM",10,"BM",10,0)+SUM(L5:L26) -> 203
B33: Change Skill Base Power? | D33: New Base Power: | L33: * inclusive of skills that increase attack like bow expert/crossbow expert
B34: No | D34: 280
B36: Yes
B37: No

Sheet gear templates
B2: Low | H2: High
A3: Hero & Paladin | B3: 18 | F3: 140 | H3: 21 | L3: 150
B6: 17 | C6: 31 | H6: 21 | I6: 40
B7: 23 | C7: 7 | H7: 60 | I7: 8
B8: 8 | C8: 12
F9: 12 | L9: 20
F10: 10 | L10: 20
F11: 15 | L11: 20
C14: 10 | H14: 15
B15: 2 | C15: 2 | H15: 6 | I15: 6
B16: 6 | H16: 10 | I16: 5
B17: 22 | C17: 23 | H17: 22 | I17: 23
I18: 5
B19: 2 | C19: 2 | L19: 3
B20: 3 | C20: 3 | H20: 8 | I20: 5
B21: 2 | C21: 2 | H21: 5 | I21: 5
B22: 1 | C22: 1 | H22: 3 | I22: 2
B23: 3 | C23: 3 | F23: 1 | H23: 3 | I23: 3 | L23: 1
B25: 700 | C25: 22 | D25: 4 | E25: 4 | H25: 999 | I25: 23 | J25: 4 | K25: 4
A28: Hero + Enrage | B28: 18 | F28: 140 | H28: 21 | L28: 150
B31: 17 | C31: 31 | H31: 21 | I31: 40
B32: 23 | C32: 7 | H32: 60 | I32: 8
B33: 8 | C33: 12
A34: Enrage buff added on this row | F34: 29 | L34: 37
F35: 10 | L35: 20
F36: 15 | L36: 20
C39: 10 | H39: 15
B40: 2 | C40: 2 | H40: 6 | I40: 6
B41: 6 | H41: 10 | I41: 5
B42: 22 | C42: 23 | H42: 22 | I42: 23
I43: 5
B44: 2 | C44: 2 | L44: 3
B45: 3 | C45: 3 | H45: 8 | I45: 5
B46: 2 | C46: 2 | H46: 5 | I46: 5
B47: 1 | C47: 1 | H47: 3 | I47: 2
B48: 3 | C48: 3 | F48: 1 | H48: 3 | I48: 3 | L48: 1
B50: 700 | C50: 22 | D50: 4 | E50: 4 | H50: 999 | I50: 23 | J50: 4 | K50: 4
A52: DrK | B52: 18 | F52: 127 | H52: 21 | L52: 139 | N52: Dark Knight | Q52: Dark Knight
N53: Equipment: | Q53: Equipment:
N54: atk pot 60 watk | Q54: atk pot 100 watk
...

Sheet meso explosion
A1: Dropping rate (bags dropped) | B1: 200 | C1: per min | E1: How long do you drop for: | F1: 120 | G1: s | J1: ratio = (aMoneyAmountDbl * 0.82 + 28.0) / 5300;
A2: Amount of mesos (integer please) | B2: 7000 | E2: How long you will bomb: | F2: =F1/60*B1/10 -> 40 | G2: s | J2: else
A3: Mesos used per min | B3: =B1*B2 -> 1400000 | E3: Currently it is assumed that you aren't dropping mesos as you bomb. Is that right? | J3: ratio = aMoneyAmountDbl / (double)(aMoneyAmount + 5250);
C4: ratio | D4: =IF($B$2>1000,$B$2/($B$2+5250),($B$2*0.82+28)/5300) -> 0.57142857
C5: Avg Damage | D5: =ROUNDDOWN(50000*0.75*$D$4,0) -> 21428
C6: After speed bombing | D6: =D5*2 -> 42856 | J6: MIN: (50 * Skill->XValue) * 0.5 * (Mesos / (MesoPool + 5250)) | N6: xvalue of ME at lv 30 is 1000
C7: DPS | D7: =D6*B1/60 -> 142853.33 | J7: MAX: (50 * Skill->XValue) * (Mesos / (MesoPool + 5250))
A8: Speed bombing. ME takes 0.75 to animate; each bag explosion takes 0.1 to animate. Each ME destroys 20 bags but only bombs 15 bags. i.e. if you cast ME repeatedly, you can bomb a set of 7.5 bags twice on average. Which means the effective damage of each bag is doubled
A12: 500 | B12: 0.082641509 | C12: 3099.0566
A13: 1000 | B13: 0.16 | C13: 6000
A14: 1500 | B14: 0.22222222 | C14: 8333.3333
A15: 2000 | B15: 0.27586207 | C15: 10344.828
A16: 2500 | B16: 0.32258065 | C16: 12096.774
A17: 3000 | B17: 0.36363636 | C17: 13636.364
A18: 3500 | B18: 0.4 | C18: 15000
A19: 4000 | B19: 0.43243243 | C19: 16216.216
A20: 4500 | B20: 0.46153846 | C20: 17307.692
A21: 5000 | B21: 0.48780488 | C21: 18292.683
A22: 5500 | B22: 0.51162791 | C22: 19186.047
A23: 6000 | B23: 0.53333333 | C23: 20000
... A111: 50000 | B111: 0.90497738 | C111: 33936.652

Sheet dmg
A1: Dmg cap: | B1: 199999
A7: Class | B7: Skill(s) | C7: Time (s) | D7: Base Power | E7: Single line dmg w/o crit (%) | F7: Single line dmg w/ crit (%) | G7: Single line dmg w/ SE (%) | H7: Range(cap) w/o crit | I7: Range(cap) w/ crit | J7: Range(cap) w/ SE | K7: Adjusted range w/o crit | L7: Adjusted range w/ crit | M7: Adjusted range w/ SE | N7: Average Damage | O7: DPS | R7: Dynamic list
B8: None/Idle | O8: 0 | R8: None/Idle
A9: Sair | B9: Battleship Cannon | C9: =VLOOKUP('range calculator'!E11,'Attack Speed'!A2:AI7,2,true) -> 0.6 | D9: =IF('range calculator'!$B$34="Yes",'range calculator'!$D$34,380) -> 380 | E9: =D9*1.2*IF('range calculator'!$D$16="Yes",1.5,1) -> 456 | F9: -- | G9: =(D9+140)*1.2*IF('range calculator'!$D$16="Yes",1.5,1) -> 624 | H9: =$B$1/(E9%) -> 43859.43 | J9: =$B$1/(G9%) -> 32051.122 | K9: =IF(H9<='range calculator'!$E$19,(H9+'range calculator'!$E$18)/2*(H9-'range calculator'!$E$18)/('range calculator'!$E$19-'range calculator'!$E$18)+H9*(1-(H9-'range calculator'!$E$18)/('range calculator'!$E$19-'range calculator'!$E$18)),'range calculator'!$D$20) -> 17629 | L9: -- | M9: =IF(J9<='range calculator'!$E$19,(J9+'range calculator'!$E$18)/2*(J9-'range calculator'!$E$18)/('range calculator'!$E$19-'range calculator'!$E$18)+J9*(1-(J9-'range calculator'!$E$18)/('range calculator'!$E$19-'range calculator'!$E$18)),'range calculator'!$D$20) -> 17629 | N9: =IF('range calculator'!$D$13="Yes",E9%*0.85*K9+G9%*0.15*M9, E9%*K9)*4 -> 339322.99 | O9: =N9/C9 -> 565538.32 | R9: =IFERROR(__xludf.DUMMYFUNCTION("SORT(FILTER(B9:B1009,'range calculator'!$D$5=A9:A1009),2,TRUE)"),"Spear Crusher") -> Spear Crusher
A10: Sair | B10: Rapid Fire | C10: 0.12 | D10: =IF('range calculator'!$B$34="Yes",'range calculator'!$D$34,200) -> 200 | E10: =D10*1.2*IF('range calculator'!$D$16="Yes",1.5,1) -> 240 | F10: -- | G10: =(D10+140)*1.2*IF('range calculator'!$D$16="Yes",1.5,1) -> 408 | H10: =$B$1/(E10%) -> 83332.917 | J10: =$B$1/(G10%) -> 49019.363 | K10: =IF(H10<='range calculator'!$E$19,(H10+'range calculator'!$E$18)/2*(H10-'range calculator'!$E$18)/('range calculator'!$E$19-'range calculator'!$E$18)+H10*(1-(H10-'range calculator'!$E$18)/('range calculator'!$E$19-'range calculator'!$E$18)),'range calculator'!$D$20) -> 17629 | L10: -- | M10: =IF(J10<='range calculator'!$E$19,(J10+'range calculator'!$E$18)/2*(J10-'range calculator'!$E$18)/('range calculator'!$E$19-'range calculator'!$E$18)+J10*(1-(J10-'range calculator'!$E$18)/('range calculator'!$E$19-'range calculator'!$E$18)),'range calculator'!$D$20) -> 17629 | N10: =IF('range calculator'!$D$13="Yes",E10%*0.85*K10+G10%*0.15*M10,E10%*K10) -> 46752.108 | O10: =N10/C10 -> 389600.9
A11: Sair | B11: Octopus | C11: 0.917 | E11: -- | F11: -- | G11: -- | H11: -- | I11: -- | J11: -- | K11: -- | L11: -- | M11: -- | N11: =('range calculator'!$I$31*4.25+'range calculator'!$H$31*2)*500/200*26 -> 200443.75 | O11: =N11/C11 -> 218586.42
A12: NL | B12: Triple Throw 30 | C12: 0.6 | D12: =IF('range calculator'!$B$34="Yes",'range calculator'!$D$34,150) -> 150 | E12: =D12*IF('range calculator'!$D$16="Yes",1.5,1) -> 150 | F12: =(150+100)*IF('range calculator'!$D$16="Yes",1.5,1) -> 250 | G12: =(D12+100+140)*IF('range calculator'!$D$16="Yes",1.5,1) -> 390 | H12: =$B$1/(E12%) -> 133332.67 | I12: =$B$1/(F12%) -> 79999.6 | J12: =$B$1/(G12%) -> 51281.795 | K12: =IF(H12<='range calculator'!$F$19,(H12+'range calculator'!$F$18)/2*(H12-'range calculator'!$F$18)/('range calculator'!$F$19-'range calculator'!$F$18)+H12*(1-(H12-'range calculator'!$F$18)/('range calculator'!$F$19-'range calculator'!$F$18)),('range calculator'!$F$18+'range calculator'!$F$19)/2) -> #DIV/0! | L12: =IF(I12<='range calculator'!$F$19,(I12+'range calculator'!$F$18)/2*(I12-'range calculator'!$F$18)/('range calculator'!$F$19-'range calculator'!$F$18)+I12*(1-(I12-'range calculator'!$F$18)/('range calculator'!$F$19-'range calculator'!$F$18)),('range calculator'!$F$18+'range calculator'!$F$19)/2) -> #DIV/0! | M12: =IF(J12<='range calculator'!$F$19,(J12+'range calculator'!$F$18)/2*(J12-'range calculator'!$F$18)/('range calculator'!$F$19-'range calculator'!$F$18)+J12*(1-(J12-'range calculator'!$F$18)/('range calculator'!$F$19-'range calculator'!$F$18)),('range calculator'!$F$18+'range calculator'!$F$19)/2) -> #DIV/0! | N12: =IF('range calculator'!$D$13="Yes", 0.35*E12%*K12+0.65*G12%*M12, 0.5*E12%*K12%+0.5*F12%*L12)*3*1.5 -> #DIV/0! | O12: =N12/C12 -> #DIV/0!
A13: NL | B13: Triple Throw 20 | C13: 0.6 | D13: =IF('range calculator'!$B$34="Yes",'range calculator'!$D$34,140) -> 140 | E13: =D13*IF('range calculator'!$D$16="Yes",1.5,1) -> 140 | F13: =(140+100)*IF('range calculator'!$D$16="Yes",1.5,1) -> 240 | G13: =(D13+100+140)*IF('range calculator'!$D$16="Yes",1.5,1) -> 380 | H13: =$B$1/(E13%) -> 142856.43 | I13: =$B$1/(F13%) -> 83332.917 | J13: =$B$1/(G13%) -> 52631.316 | K13: =IF(H13<='range calculator'!$F$19,(H13+'range calculator'!$F$18)/2*(H13-'range calculator'!$F$18)/('range calculator'!$F$19-'range calculator'!$F$18)+H13*(1-(H13-'range calculator'!$F$18)/('range calculator'!$F$19-'range calculator'!$F$18)),('range calculator'!$F$18+'range calculator'!$F$19)/2) -> #DIV/0! | L13: =IF(I13<='range calculator'!$F$19,(I13+'range calculator'!$F$18)/2*(I13-'range calculator'!$F$18)/('range calculator'!$F$19-'range calculator'!$F$18)+I13*(1-(I13-'range calculator'!$F$18)/('range calculator'!$F$19-'range calculator'!$F$18)),('range calculator'!$F$18+'range calculator'!$F$19)/2) -> #DIV/0! | M13: =IF(J13<='range calculator'!$F$19,(J13+'range calculator'!$F$18)/2*(J13-'range calculator'!$F$18)/('range calculator'!$F$19-'range calculator'!$F$18)+J13*(1-(J13-'range calculator'!$F$18)/('range calculator'!$F$19-'range calculator'!$F$18)),('range calculator'!$F$18+'range calculator'!$F$19)/2) -> #DIV/0! | N13: =IF('range calculator'!$D$13="Yes", 0.35*E13%*K13+0.65*G13%*M13, 0.5*E13%*K13%+0.5*F13%*L13)*3*1.5 -> #DIV/0! | O13: =N13/C13 -> #DIV/0!
A14: BM | B14: Hurricane | C14: 0.12 | D14: =IF('range calculator'!$B$34="Yes",'range calculator'!$D$34,100) -> 100 | E14: =D14*IF('range calculator'!$D$16="Yes",1.5,1) -> 100 | F14: =(100+100)*IF('range calculator'!$D$16="Yes",1.5,1) -> 200 | G14: =(D14+100+140)*IF('range calculator'!$D$16="Yes",1.5,1) -> 340 | H14: =$B$1/(E14%) -> 199999 | I14: =$B$1/(F14%) -> 99999.5 | J14: =$B$1/(G14%) -> 58823.235 | K14: =IF(H14<='range calculator'!$E$19,(H14+'range calculator'!$E$18)/2*(H14-'range calculator'!$E$18)/('range calculator'!$E$19-'range calculator'!$E$18)+H14*(1-(H14-'range calculator'!$E$18)/('range calculator'!$E$19-'range calculator'!$E$18)),'range calculator'!$D$20) -> 17629 | L14: =IF(I14<='range calculator'!$E$19,(I14+'range calculator'!$E$18)/2*(I14-'range calculator'!$E$18)/('range calculator'!$E$19-'range calculator'!$E$18)+I14*(1-(I14-'range calculator'!$E$18)/('range calculator'!$E$19-'range calculator'!$E$18)),'range calculator'!$D$20) -> 17629 | M14: =IF(J14<='range calculator'!$E$19,(J14+'range calculator'!$E$18)/2*(J14-'range calculator'!$E$18)/('range calculator'!$E$19-'range calculator'!$E$18)+J14*(1-(J14-'range calculator'!$E$18)/('range calculator'!$E$19-'range calculator'!$E$18)),'range calculator'!$D$20) -> 17629 | N14: =IF('range calculator'!$D$13="Yes",0.45*E14%*K14+0.55*G14%*M14,0.6*E14%*K14+0.4*F14%*L14) -> 40899.28 | O14: =N14/C14 -> 340827.33
A15: Hero | B15: Brandish (Sword) | C15: =VLOOKUP('range calculator'!$E$11,'Attack Speed'!$A$2:AI$7,5,true) -> 0.63 | D15: =IF('range calculator'!$B$34="Yes",'range calculator'!$D$34,260) -> 260 | E15: =D15*1.9*IF('range calculator'!$D$16="Yes",1.5,1) -> 494 | F15: -- | G15: =(D15+140)*1.9*IF('range calculator'!$D$16="Yes",1.5,1) -> 760 | H15: =$B$1/(E15%) -> 40485.628 | J15: =$B$1/(G15%) -> 26315.658 | K15: =IF(H15<='range calculator'!$E$19,(H15+'range calculator'!$E$18)/2*(H15-'range calculator'!$E$18)/('range calculator'!$E$19-'range calculator'!$E$18)+H15*(1-(H15-'range calculator'!$E$18)/('range calculator'!$E$19-'range calculator'!$E$18)),'range calculator'!$D$20) -> 17629 | L15: -- | M15: =IF(J15<='range calculator'!$E$19,(J15+'range calculator'!$E$18)/2*(J15-'range calculator'!$E$18)/('range calculator'!$E$19-'range calculator'!$E$18)+J15*(1-(J15-'range calculator'!$E$18)/('range calculator'!$E$19-'range calculator'!$E$18)),'range calculator'!$D$20) -> 17629 | N15: =IF('range calculator'!$D$13="Yes",E15%*0.85*K15+G15%*0.15*M15, E15%*K15)*2 -> 188242.46 | O15: =N15/C15 -> 298797.56
B16: Brandish (Axe, Slash) | C16: =VLOOKUP('range calculator'!$E$11,'Attack Speed'!$A$2:AI$7,5,true) -> 0.63 | D16: =IF('range calculator'!$B$34="Yes",'range calculator'!$D$34,260) -> 260 | E16: =D16*1.9*IF('range calculator'!$D$16="Yes",1.5,1) -> 494 | F16: -- | G16: =(D16+140)*1.9*IF('range calculator'!$D$16="Yes",1.5,1) -> 760 | H16: =$B$1/(E16%) -> 40485.628 | J16: =$B$1/(G16%) -> 26315.658 | K16: =IF(H16<='range calculator'!$E$19,(H16+'range calculator'!$E$18)/2*(H16-'range calculator'!$E$18)/('range calculator'!$E$19-'range calculator'!$E$18)+H16*(1-(H16-'range calculator'!$E$18)/('range calculator'!$E$19-'range calculator'!$E$18)),AVERAGE('range calculator'!$E$18,'range calculator'!$E$19)) -> 17629 | L16: -- | M16: =IF(J16<='range calculator'!$E$19,(J16+'range calculator'!$E$18)/2*(J16-'range calculator'!$E$18)/('range calculator'!$E$19-'range calculator'!$E$18)+J16*(1-(J16-'range calculator'!$E$18)/('range calculator'!$E$19-'range calculator'!$E$18)),AVERAGE('range calculator'!$E$18,'range calculator'!$E$19)) -> 17629 | N16: =IF('range calculator'!$D$13="Yes",E16%*0.85*K16+G16%*0.15*M16, E16%*K16)*2 -> 188242.46 | O16: =N16/C16 -> 298797.56
B17: Brandish (Axe, Stab) | C17: =VLOOKUP('range calculator'!$E$11,'Attack Speed'!$A$2:AI$7,5,true) -> 0.63 | D17: =IF('range calculator'!$B$34="Yes",'range calculator'!$D$34,260) -> 260 | E17: =D17*1.9*IF('range calculator'!$D$16="Yes",1.5,1) -> 494 | F17: -- | G17: =(D17+140)*1.9*IF('range calculator'!$D$16="Yes",1.5,1) -> 760 | H17: =$B$1/(E17%) -> 40485.628 | J17: =$B$1/(G17%) -> 26315.658 | K17: =IF(H17<='range calculator'!$F$19,(H17+'range calculator'!$F$18)/2*(H17-'range calculator'!$F$18)/('range calculator'!$F$19-'range calculator'!$F$18)+H17*(1-(H17-'range calculator'!$F$18)/('range calculator'!$F$19-'range calculator'!$F$18)),AVERAGE('range calculator'!$F$18,'range calculator'!$F$19)) -> #DIV/0! | L17: -- | M17: =IF(J17<='range calculator'!$F$19,(J17+'range calculator'!$F$18)/2*(J17-'range calculator'!$F$18)/('range calculator'!$E$19-'range calculator'!$F$18)+J17*(1-(J17-'range calculator'!$F$18)/('range calculator'!$F$19-'range calculator'!$F$18)),AVERAGE('range calculator'!$F$18,'range calculator'!$F$19)) -> #DIV/0! | N17: =IF('range calculator'!$D$13="Yes",E17%*0.85*K17+G17%*0.15*M17, E17%*K17)*2 -> #DIV/0! | O17: =N17/C17 -> #DIV/0!
A18: Hero | B18: Brandish (Axe) | C18: =VLOOKUP('range calculator'!$E$11,'Attack Speed'!$A$2:AI$7,5,true) -> 0.63 | E18: -- | F18: -- | G18: -- | H18: -- | I18: -- | J18: -- | K18: -- | L18: -- | M18: -- | N18: =(N16+N17)/2 -> #DIV/0! | O18: =N18/C18 -> #DIV/0!
A19: MM | B19: Strafe (MM) | C19: =VLOOKUP('range calculator'!$E$11,'Attack Speed'!$A$2:AI$7,3,true) -> 0.6 | D19: =IF('range calculator'!$B$34="Yes",'range calculator'!$D$34,125) -> 125 | E19: =D19*IF('range calculator'!$D$16="Yes",1.5,1) -> 125 | F19: =(125+100)*IF('range calculator'!$D$16="Yes",1.5,1) -> 225 | G19: =(D19+100+140)*IF('range calculator'!$D$16="Yes",1.5,1) -> 365 | H19: =$B$1/(E19%) -> 159999.2 | I19: =$B$1/(F19%) -> 88888.444 | J19: =$B$1/(G19%) -> 54794.247 | K19: =IF(H19<='range calculator'!$E$19,(H19+'range calculator'!$E$18)/2*(H19-'range calculator'!$E$18)/('range calculator'!$E$19-'range calculator'!$E$18)+H19*(1-(H19-'range calculator'!$E$18)/('range calculator'!$E$19-'range calculator'!$E$18)),'range calculator'!$D$20) -> 17629 | L19: =IF(I19<='range calculator'!$E$19,(I19+'range calculator'!$E$18)/2*(I19-'range calculator'!$E$18)/('range calculator'!$E$19-'range calculator'!$E$18)+I19*(1-(I19-'range calculator'!$E$18)/('range calculator'!$E$19-'range calculator'!$E$18)),'range calculator'!$D$20) -> 17629 | M19: =IF(J19<='range calculator'!$E$19,(J19+'range calculator'!$E$18)/2*(J19-'range calculator'!$E$18)/('range calculator'!$E$19-'range calculator'!$E$18)+J19*(1-(J19-'range calculator'!$E$18)/('range calculator'!$E$19-'range calculator'!$E$18)),'range calculator'!$D$20) -> 17629 | N19: =IF('range calculator'!$D$13="Yes",0.45*E19%*K19+0.55*G19%*M19,0.6*E19%*K19+0.4*F19%*L19)*4 -> 181226.12 | O19: =N19/C19 -> 302043.53
A20: MM | B20: Snipe | C20: =VLOOKUP('range calculator'!$E$11,'Attack Speed'!$A$2:AI$7,3,true) -> 0.6 | E20: -- | F20: -- | G20: -- | H20: -- | I20: -- | J20: -- | K20: -- | L20: -- | M20: -- | N20: -- | O20: =195000/C20 -> 325000
A21: Bucc | B21: Demolition | C21: 2.34 | D21: =IF('range calculator'!$B$34="Yes",'range calculator'!$D$34,500) -> 500 | E21: =D21*IF('range calculator'!$D$16="Yes",1.5,1) -> 500 | F21: -- | G21: =(D21+140)*IF('range calculator'!$D$16="Yes",1.5,1) -> 640 | H21: =$B$1/(E21%) -> 39999.8 | J21: =$B$1/(G21%) -> 31249.844 | K21: =IF(H21<='range calculator'!$E$19,(H21+'range calculator'!$E$18)/2*(H21-'range calculator'!$E$18)/('range calculator'!$E$19-'range calculator'!$E$18)+H21*(1-(H21-'range calculator'!$E$18)/('range calculator'!$E$19-'range calculator'!$E$18)),'range calculator'!$D$20) -> 17629 | L21: -- | M21: =IF(J21<='range calculator'!$E$19,(J21+'range calculator'!$E$18)/2*(J21-'range calculator'!$E$18)/('range calculator'!$E$19-'range calculator'!$E$18)+J21*(1-(J21-'range calculator'!$E$18)/('range calculator'!$E$19-'range calculator'!$E$18)),'range calculator'!$D$20) -> 17629 | N21: =IF('range calculator'!$D$13="Yes",E21%*0.85*K21+G21%*0.15*M21, E21%*K21)*8 -> 734776.72 | O21: =N21/C21 -> 314007.15
B22: Barrage (normal) | D22: =IF('range calculator'!$B$34="Yes",'range calculator'!$D$34,330) -> 330 | E22: =D22*IF('range calculator'!$D$16="Yes",1.5,1) -> 330 | F22: -- | G22: =(D22+140)*IF('range calculator'!$D$16="Yes",1.5,1) -> 470 | H22: =$B$1/(E22%) -> 60605.758 | J22: =$B$1/(G22%) -> 42552.979 | K22: =IF(H22<='range calculator'!$E$19,(H22+'range calculator'!$E$18)/2*(H22-'range calculator'!$E$18)/('range calculator'!$E$19-'range calculator'!$E$18)+H22*(1-(H22-'range calculator'!$E$18)/('range calculator'!$E$19-'range calculator'!$E$18)),'range calculator'!$D$20) -> 17629 | L22: -- | M22: =IF(J22<='range calculator'!$E$19,(J22+'range calculator'!$E$18)/2*(J22-'range calculator'!$E$18)/('range calculator'!$E$19-'range calculator'!$E$18)+J22*(1-(J22-'range calculator'!$E$18)/('range calculator'!$E$19-'range calculator'!$E$18)),'range calculator'!$D$20) -> 17629 | N22: =IF('range calculator'!$D$13="Yes",E22%*0.85*K22+G22%*0.15*M22, E22%*K22)*4 -> 247511.16 | O22: --
B23: Barrage (5th) | D23: =IF('range calculator'!$B$34="Yes",'range calculator'!$D$34,330) -> 330 | E23: =(D23*2)*IF('range calculator'!$D$16="Yes",1.5,1) -> 660 | F23: -- | G23: =(D23*2+140*2)*IF('range calculator'!$D$16="Yes",1.5,1) -> 940 | H23: =$B$1/(E23%) -> 30302.879 | J23: =$B$1/(G23%) -> 21276.489 | K23: =IF(H23<='range calculator'!$E$19,(H23+'range calculator'!$E$18)/2*(H23-'range calculator'!$E$18)/('range calculator'!$E$19-'range calculator'!$E$18)+H23*(1-(H23-'range calculator'!$E$18)/('range calculator'!$E$19-'range calculator'!$E$18)),'range calculator'!$D$20) -> 17629 | L23: -- | M23: =IF(J23<='range calculator'!$E$19,(J23+'range calculator'!$E$18)/2*(J23-'range calculator'!$E$18)/('range calculator'!$E$19-'range calculator'!$E$18)+J23*(1-(J23-'range calculator'!$E$18)/('range calculator'!$E$19-'range calculator'!$E$18)),'range calculator'!$D$20) -> 17629 | N23: =IF('range calculator'!$D$13="Yes",E23%*0.85*K23+G23%*0.15*M23, E23%*K23) -> 123755.58 | O23: --
B24: Barrage (6th) | D24: =IF('range calculator'!$B$34="Yes",'range calculator'!$D$34,330) -> 330 | E24: =(D24*4)*IF('range calculator'!$D$16="Yes",1.5,1) -> 1320 | F24: -- | G24: =(D24*4+140*4)*IF('range calculator'!$D$16="Yes",1.5,1) -> 1880 | H24: =$B$1/(E24%) -> 15151.439 | J24: =$B$1/(G24%) -> 10638.245 | K24: =IF(H24<='range calculator'!$E$19,(H24+'range calculator'!$E$18)/2*(H24-'range calculator'!$E$18)/('range calculator'!$E$19-'range calculator'!$E$18)+H24*(1-(H24-'range calculator'!$E$18)/('range calculator'!$E$19-'range calculator'!$E$18)),'range calculator'!$D$20) -> 15141.884 | L24: -- | M24: =IF(J24<='range calculator'!$E$19,(J24+'range calculator'!$E$18)/2*(J24-'range calculator'!$E$18)/('range calculator'!$E$19-'range calculator'!$E$18)+J24*(1-(J24-'range calculator'!$E$18)/('range calculator'!$E$19-'range calculator'!$E$18)),'range calculator'!$D$20) -> 9076.6985 | N24: =IF('range calculator'!$D$13="Yes",E24%*0.85*K24+G24%*0.15*M24, E24%*K24) -> 195488.22 | O24: --
B25: Dragon Strike | D25: =IF('range calculator'!$B$34="Yes",'range calculator'!$D$34,900) -> 900 | E25: =D25*IF('range calculator'!$D$16="Yes",1.5,1) -> 900 | F25: -- | G25: =(D25+140)*IF('range calculator'!$D$16="Yes",1.5,1) -> 1040 | H25: =$B$1/(E25%) -> 22222.111 | I25: -- | J25: =$B$1/(G25%) -> 19230.673 | K25: =IF(H25<='range calculator'!$E$19,(H25+'range calculator'!$E$18)/2*(H25-'range calculator'!$E$18)/('range calculator'!$E$19-'range calculator'!$E$18)+H25*(1-(H25-'range calculator'!$E$18)/('range calculator'!$E$19-'range calculator'!$E$18)),'range calculator'!$D$20) -> 17629 | L25: -- | M25: =IF(J25<='range calculator'!$E$19,(J25+'range calculator'!$E$18)/2*(J25-'range calculator'!$E$18)/('range calculator'!$E$19-'range calculator'!$E$18)+J25*(1-(J25-'range calculator'!$E$18)/('range calculator'!$E$19-'range calculator'!$E$18)),'range calculator'!$D$20) -> 17499.945 | N25: =IF('range calculator'!$D$13="Yes",E25%*0.85*K25+G25%*0.15*M25, E25%*K25) -> 162161.76 | O25: --
A26: Bucc | B26: Barrage + Dragon Strike | C26: 2.34 | E26: -- | F26: -- | G26: -- | H26: -- | I26: -- | J26: -- | K26: -- | L26: -- | M26: -- | N26: =$N$22+$N$23+$N$24+$N$25 -> 728916.73 | O26: =N26/C26 -> 311502.88
A27: DrK | B27: Spear Crusher | C27: =VLOOKUP('range calculator'!$E$11,'Attack Speed'!$A$2:AI$7,4,true) -> 0.81 | D27: =IF('range calculator'!$B$34="Yes",'range calculator'!$D$34,170) -> 170 | E27: =D27*2*IF('range calculator'!$D$16="Yes",1.5,1) -> 340 | F27: -- | G27: =(D27+140)*2*IF('range calculator'!$D$16="Yes",1.5,1) -> 620 | H27: =$B$1/(E27%) -> 58823.235 | J27: =$B$1/(G27%) -> 32257.903 | K27: =IF(H27<='range calculator'!$E$19,(H27+'range calculator'!$E$18)/2*(H27-'range calculator'!$E$18)/('range calculator'!$E$19-'range calculator'!$E$18)+H27*(1-(H27-'range calculator'!$E$18)/('range calculator'!$E$19-'range calculator'!$E$18)),'range calculator'!$D$20) -> 17629 | L27: -- | M27: =IF(J27<='range calculator'!$E$19,(J27+'range calculator'!$E$18)/2*(J27-'range calculator'!$E$18)/('range calculator'!$E$19-'range calculator'!$E$18)+J27*(1-(J27-'range calculator'!$E$18)/('range calculator'!$E$19-'range calculator'!$E$18)),'range calculator'!$D$20) -> 17629 | N27: =IF('range calculator'!$D$13="Yes",E27%*0.85*K27+G27%*0.15*M27, E27%*K27)*3 -> 202028.34 | O27: =N27/C27 -> 249417.7
A28: Pally | B28: Blast (holy charge) (sword) | C28: =VLOOKUP('range calculator'!$E$11,'Attack Speed'!$A$2:AI$7,6,true) -> 0.63 | D28: =IF('range calculator'!$B$34="Yes",'range calculator'!$D$34,580) -> 580 | E28: =D28*1.4*IF('range calculator'!$D$16="Yes",1.5,1) -> 812 | F28: -- | G28: =D28*1.4+140*IF('range calculator'!$D$16="Yes",1.5,1) -> 952 | H28: =$B$1/(E28%) -> 24630.419 | I28: -- | J28: =$B$1/(G28%) -> 21008.298 | K28: =IF(H28<='range calculator'!$E$19,(H28+'range calculator'!$E$18)/2*(H28-'range calculator'!$E$18)/('range calculator'!$E$19-'range calculator'!$E$18)+H28*(1-(H28-'range calculator'!$E$18)/('range calculator'!$E$19-'range calculator'!$E$18)),'range calculator'!$D$20) -> 17629 | L28: -- | M28: =IF(J28<='range calculator'!$E$19,(J28+'range calculator'!$E$18)/2*(J28-'range calculator'!$E$18)/('range calculator'!$E$19-'range calculator'!$E$18)+J28*(1-(J28-'range calculator'!$E$18)/('range calculator'!$E$19-'range calculator'!$E$18)),'range calculator'!$D$20) -> 17629 | N28: =IF('range calculator'!$D$13="Yes",E28%*0.85*K28+G28%*0.15*M28, E28%*K28) -> 146849.57 | O28: =N28/C28 -> 233094.56
A29: Pally | B29: Blast (f/i/l charge) (sword) | C29: =VLOOKUP('range calculator'!$E$11,'Attack Speed'!$A$2:AI$7,3,true) -> 0.6 | D29: =IF('range calculator'!$B$34="Yes",'range calculator'!$D$34,580) -> 580 | E29: =D29*1.3*IF('range calculator'!$D$16="Yes",1.5,1) -> 754 | F29: -- | G29: =D29*1.3+140*IF('range calculator'!$D$16="Yes",1.5,1) -> 894 | H29: =$B$1/(E29%) -> 26525.066 | I29: -- | J29: =$B$1/(G29%) -> 22371.253 | K29: =IF(H29<='range calculator'!$E$19,(H29+'range calculator'!$E$18)/2*(H29-'range calculator'!$E$18)/('range calculator'!$E$19-'range calculator'!$E$18)+H29*(1-(H29-'range calculator'!$E$18)/('range calculator'!$E$19-'range calculator'!$E$18)),'range calculator'!$D$20) -> 17629 | L29: -- | M29: =IF(J29<='range calculator'!$E$19,(J29+'range calculator'!$E$18)/2*(J29-'range calculator'!$E$18)/('range calculator'!$E$19-'range calculator'!$E$18)+J29*(1-(J29-'range calculator'!$E$18)/('range calculator'!$E$19-'range calculator'!$E$18)),'range calculator'!$D$20) -> 17629 | N29: =IF('range calculator'!$D$13="Yes",E29%*0.85*K29+G29%*0.15*M29, E29%*K29) -> 136624.75 | O29: =N29/C29 -> 227707.92
B30: Blast (holy charge) (BW, Slash) | C30: =VLOOKUP('range calculator'!$E$11,'Attack Speed'!$A$2:AI$7,5,true) -> 0.63 | D30: =IF('range calculator'!$B$34="Yes",'range calculator'!$D$34,580) -> 580 | E30: =D30*1.4*IF('range calculator'!$D$16="Yes",1.5,1) -> 812 | F30: -- | G30: =D30*1.4+140*IF('range calculator'!$D$16="Yes",1.5,1) -> 952 | H30: =$B$1/(E30%) -> 24630.419 | J30: =$B$1/(G30%) -> 21008.298 | K30: =IF(H30<='range calculator'!$E$19,(H30+'range calculator'!$E$18)/2*(H30-'range calculator'!$E$18)/('range calculator'!$E$19-'range calculator'!$E$18)+H30*(1-(H30-'range calculator'!$E$18)/('range calculator'!$E$19-'range calculator'!$E$18)),AVERAGE('range calculator'!$E$18,'range calculator'!$E$19)) -> 17629 | L30: -- | M30: =IF(J30<='range calculator'!$E$19,(J30+'range calculator'!$E$18)/2*(J30-'range calculator'!$E$18)/('range calculator'!$E$19-'range calculator'!$E$18)+J30*(1-(J30-'range calculator'!$E$18)/('range calculator'!$E$19-'range calculator'!$E$18)),AVERAGE('range calculator'!$E$18,'range calculator'!$E$19)) -> 17629 | N30: =IF('range calculator'!$D$13="Yes",E30%*0.85*K30+G30%*0.15*M30, E30%*K30) -> 146849.57 | O30: =N30/C30 -> 233094.56
B31: Blast (holy charge) (BW, Stab) | C31: =VLOOKUP('range calculator'!$E$11,'Attack Speed'!$A$2:AI$7,5,true) -> 0.63 | D31: =IF('range calculator'!$B$34="Yes",'range calculator'!$D$34,580) -> 580 | E31: =D31*1.4*IF('range calculator'!$D$16="Yes",1.5,1) -> 812 | F31: -- | G31: =D30*1.4+140*IF('range calculator'!$D$16="Yes",1.5,1) -> 952 | H31: =$B$1/(E31%) -> 24630.419 | J31: =$B$1/(G31%) -> 21008.298 | K31: =IF(H31<='range calculator'!$F$19,(H31+'range calculator'!$F$18)/2*(H31-'range calculator'!$F$18)/('range calculator'!$F$19-'range calculator'!$F$18)+H31*(1-(H31-'range calculator'!$F$18)/('range calculator'!$F$19-'range calculator'!$F$18)),AVERAGE('range calculator'!$F$18,'range calculator'!$F$19)) -> #DIV/0! | L31: -- | M31: =IF(J31<='range calculator'!$F$19,(J31+'range calculator'!$F$18)/2*(J31-'range calculator'!$F$18)/('range calculator'!$E$19-'range calculator'!$F$18)+J31*(1-(J31-'range calculator'!$F$18)/('range calculator'!$F$19-'range calculator'!$F$18)),AVERAGE('range calculator'!$F$18,'range calculator'!$F$19)) -> #DIV/0! | N31: =IF('range calculator'!$D$13="Yes",E31%*0.85*K31+G31%*0.15*M31, E31%*K31) -> #DIV/0! | O31: =N31/C31 -> #DIV/0!
A32: Pally | B32: Blast (holy charge) (BW) | C32: =VLOOKUP('range calculator'!$E$11,'Attack Speed'!$A$2:AI$7,5,true) -> 0.63 | E32: -- | F32: -- | G32: -- | H32: -- | I32: -- | J32: -- | K32: -- | L32: -- | M32: -- | N32: =(N30*3+N31*2)/5 -> #DIV/0! | O32: =N32/C32 -> #DIV/0!
B33: Blast (f/i/l charge) (BW, Slash) | C33: =VLOOKUP('range calculator'!$E$11,'Attack Speed'!$A$2:AI$7,5,true) -> 0.63 | D33: =IF('range calculator'!$B$34="Yes",'range calculator'!$D$34,580) -> 580 | E33: =D33*1.3*IF('range calculator'!$D$16="Yes",1.5,1) -> 754 | F33: -- | G33: =D30*1.3+140*IF('range calculator'!$D$16="Yes",1.5,1) -> 894 | H33: =$B$1/(E33%) -> 26525.066 | J33: =$B$1/(G33%) -> 22371.253 | K33: =IF(H33<='range calculator'!$E$19,(H33+'range calculator'!$E$18)/2*(H33-'range calculator'!$E$18)/('range calculator'!$E$19-'range calculator'!$E$18)+H33*(1-(H33-'range calculator'!$E$18)/('range calculator'!$E$19-'range calculator'!$E$18)),AVERAGE('range calculator'!$E$18,'range calculator'!$E$19)) -> 17629 | L33: -- | M33: =IF(J33<='range calculator'!$E$19,(J33+'range calculator'!$E$18)/2*(J33-'range calculator'!$E$18)/('range calculator'!$E$19-'range calculator'!$E$18)+J33*(1-(J33-'range calculator'!$E$18)/('range calculator'!$E$19-'range calculator'!$E$18)),AVERAGE('range calculator'!$E$18,'range calculator'!$E$19)) -> 17629 | N33: =IF('range calculator'!$D$13="Yes",E33%*0.85*K33+G33%*0.15*M33, E33%*K33) -> 136624.75 | O33: =N33/C33 -> 216864.68
B34: Blast (f/i/l charge) (BW, Stab) | C34: =VLOOKUP('range calculator'!$E$11,'Attack Speed'!$A$2:AI$7,5,true) -> 0.63 | D34: =IF('range calculator'!$B$34="Yes",'range calculator'!$D$34,580) -> 580 | E34: =D34*1.3*IF('range calculator'!$D$16="Yes",1.5,1) -> 754 | F34: -- | G34: =D30*1.3+140*IF('range calculator'!$D$16="Yes",1.5,1) -> 894 | H34: =$B$1/(E34%) -> 26525.066 | J34: =$B$1/(G34%) -> 22371.253 | K34: =IF(H34<='range calculator'!$F$19,(H34+'range calculator'!$F$18)/2*(H34-'range calculator'!$F$18)/('range calculator'!$F$19-'range calculator'!$F$18)+H34*(1-(H34-'range calculator'!$F$18)/('range calculator'!$F$19-'range calculator'!$F$18)),AVERAGE('range calculator'!$F$18,'range calculator'!$F$19)) -> #DIV/0! | L34: -- | M34: =IF(J34<='range calculator'!$F$19,(J34+'range calculator'!$F$18)/2*(J34-'range calculator'!$F$18)/('range calculator'!$E$19-'range calculator'!$F$18)+J34*(1-(J34-'range calculator'!$F$18)/('range calculator'!$F$19-'range calculator'!$F$18)),AVERAGE('range calculator'!$F$18,'range calculator'!$F$19)) -> #DIV/0! | N34: =IF('range calculator'!$D$13="Yes",E34%*0.85*K34+G34%*0.15*M34, E34%*K34) -> #DIV/0! | O34: =N34/C34 -> #DIV/0!
A35: Pally | B35: Blast (f/i/l charge) (BW) | C35: =VLOOKUP('range calculator'!$E$11,'Attack Speed'!$A$2:AI$7,5,true) -> 0.63 | E35: -- | F35: -- | G35: -- | H35: -- | I35: -- | J35: -- | K35: -- | L35: -- | M35: -- | N35: =(N33*3+N34*2)/5 -> #DIV/0! | O35: =N35/C35 -> #DIV/0!
A36: Archmage | B36: Paralyze | C36: 0.72 | D36: =IF('range calculator'!$B$34="Yes",'range calculator'!$D$34,240) -> 240 | E36: =D36*IF('range calculator'!$D$16="Yes",1.5,1) -> 240 | F36: -- | G36: =(D36+140)*IF('range calculator'!$D$16="Yes",1.5,1) -> 380 | H36: =$B$1/(E36) -> 833.32917 | I36: -- | J36: =$B$1/(G36) -> 526.31316 | K36: =IF(H36<='range calculator'!$E$19,(H36+'range calculator'!$E$18)/2*(H36-'range calculator'!$E$18)/('range calculator'!$E$19-'range calculator'!$E$18)+H36*(1-(H36-'range calculator'!$E$18)/('range calculator'!$E$19-'range calculator'!$E$18)),'range calculator'!$D$20) -> -16612.203 | L36: -- | M36: =IF(J36<='range calculator'!$E$19,(J36+'range calculator'!$E$18)/2*(J36-'range calculator'!$E$18)/('range calculator'!$E$19-'range calculator'!$E$18)+J36*(1-(J36-'range calculator'!$E$18)/('range calculator'!$E$19-'range calculator'!$E$18)),'range calculator'!$D$20) -> -17693.281 | N36: =IF('range calculator'!$D$13="Yes",E36*0.85*K36+G36*0.15*M36, E36*K36) -> -4397406.4 | O36: =N36/C36 -> -6107508.9
A37: Archmage | B37: Chain Lightning (single target) | C37: 0.69 | D37: =IF('range calculator'!$B$34="Yes",'range calculator'!$D$34,210) -> 210 | E37: =D37*IF('range calculator'!$D$16="Yes",1.5,1) -> 210 | F37: -- | G37: =(D37+140)*IF('range calculator'!$D$16="Yes",1.5,1) -> 350 | H37: =$B$1/(E37) -> 952.37619 | I37: -- | J37: =$B$1/(G37) -> 571.42571 | K37: =IF(H37<='range calculator'!$E$19,(H37+'range calculator'!$E$18)/2*(H37-'range calculator'!$E$18)/('range calculator'!$E$19-'range calculator'!$E$18)+H37*(1-(H37-'range calculator'!$E$18)/('range calculator'!$E$19-'range calculator'!$E$18)),'range calculator'!$D$20) -> -16197.53 | L37: -- | M37: =IF(J37<='range calculator'!$E$19,(J37+'range calculator'!$E$18)/2*(J37-'range calculator'!$E$18)/('range calculator'!$E$19-'range calculator'!$E$18)+J37*(1-(J37-'range calculator'!$E$18)/('range calculator'!$E$19-'range calculator'!$E$18)),'range calculator'!$D$20) -> -17533.376 | N37: =IF('range calculator'!$D$13="Yes",E37*0.85*K37+G37*0.15*M37, E37*K37) -> -3811761.3 | O37: =N37/C37 -> -5524291.8
A38: Archmage | B38: CL (chg mult to 1, 1.7, 2.19, 2.53, 2.77, 2.94 depending on no.of targets) | C38: 0.69 | D38: =IF('range calculator'!$B$34="Yes",'range calculator'!$D$34,210) -> 210 | E38: =D38*IF('range calculator'!$D$16="Yes",1.5,1) -> 210 | F38: -- | G38: =(D38+140)*IF('range calculator'!$D$16="Yes",1.5,1) -> 350 | H38: =$B$1/(E38) -> 952.37619 | I38: -- | J38: =$B$1/(G38) -> 571.42571 | K38: =IF(H38<='range calculator'!$E$19,(H38+'range calculator'!$E$18)/2*(H38-'range calculator'!$E$18)/('range calculator'!$E$19-'range calculator'!$E$18)+H38*(1-(H38-'range calculator'!$E$18)/('range calculator'!$E$19-'range calculator'!$E$18)),'range calculator'!$D$20) -> -16197.53 | L38: -- | M38: =IF(J38<='range calculator'!$E$19,(J38+'range calculator'!$E$18)/2*(J38-'range calculator'!$E$18)/('range calculator'!$E$19-'range calculator'!$E$18)+J38*(1-(J38-'range calculator'!$E$18)/('range calculator'!$E$19-'range calculator'!$E$18)),'range calculator'!$D$20) -> -17533.376 | N38: =IF('range calculator'!$D$13="Yes",E38*0.85*K38+G38*0.15*M38, E38*K38) -> -3811761.3 | O38: =N38/C38 -> -5524291.8
A39: Archmage | B39: Meteor | C39: 3.06 | D39: =IF('range calculator'!$B$34="Yes",'range calculator'!$D$34,570) -> 570 | E39: =D39*IF('range calculator'!$D$16="Yes",1.5,1) -> 570 | F39: -- | G39: =(D39+140)*IF('range calculator'!$D$16="Yes",1.5,1) -> 710 | H39: =$B$1/(E39) -> 350.87544 | I39: -- | J39: =$B$1/(G39) -> 281.68873 | K39: =IF(H39<='range calculator'!$E$19,(H39+'range calculator'!$E$18)/2*(H39-'range calculator'!$E$18)/('range calculator'!$E$19-'range calculator'!$E$18)+H39*(1-(H39-'range calculator'!$E$18)/('range calculator'!$E$19-'range calculator'!$E$18)),'range calculator'!$D$20) -> -18318.584 | L39: -- | M39: =IF(J39<='range calculator'!$E$19,(J39+'range calculator'!$E$18)/2*(J39-'range calculator'!$E$18)/('range calculator'!$E$19-'range calculator'!$E$18)+J39*(1-(J39-'range calculator'!$E$18)/('range calculator'!$E$19-'range calculator'!$E$18)),'range calculator'!$D$20) -> -18566.691 | N39: =IF('range calculator'!$D$13="Yes",E39*0.85*K39+G39*0.15*M39, E39*K39) -> -10852706 | O39: =N39/C39 -> -3546636.1
A40: Archmage | B40: Blizzard | C40: 3.06 | D40: =IF('range calculator'!$B$34="Yes",'range calculator'!$D$34,570) -> 570 | E40: =D40*IF('range calculator'!$D$16="Yes",1.5,1) -> 570 | F40: -- | G40: =(D40+140)*IF('range calculator'!$D$16="Yes",1.5,1) -> 710 | H40: =$B$1/(E40) -> 350.87544 | I40: -- | J40: =$B$1/(G40) -> 281.68873 | K40: =IF(H40<='range calculator'!$E$19,(H40+'range calculator'!$E$18)/2*(H40-'range calculator'!$E$18)/('range calculator'!$E$19-'range calculator'!$E$18)+H40*(1-(H40-'range calculator'!$E$18)/('range calculator'!$E$19-'range calculator'!$E$18)),'range calculator'!$D$20) -> -18318.584 | L40: -- | M40: =IF(J40<='range calculator'!$E$19,(J40+'range calculator'!$E$18)/2*(J40-'range calculator'!$E$18)/('range calculator'!$E$19-'range calculator'!$E$18)+J40*(1-(J40-'range calculator'!$E$18)/('range calculator'!$E$19-'range calculator'!$E$18)),'range calculator'!$D$20) -> -18566.691 | N40: =IF('range calculator'!$D$13="Yes",E40*0.85*K40+G40*0.15*M40, E40*K40) -> -10852706 | O40: =N40/C40 -> -3546636.1
A41: Bishop | B41: Genesis | C41: 2.7 | D41: =IF('range calculator'!$B$34="Yes",'range calculator'!$D$34,670) -> 670 | E41: =D41*IF('range calculator'!$D$16="Yes",1.5,1) -> 670 | F41: -- | G41: =(D41+140)*IF('range calculator'!$D$16="Yes",1.5,1) -> 810 | H41: =$B$1/(E41) -> 298.50597 | I41: -- | J41: =$B$1/(G41) -> 246.91235 | K41: =IF(H41<='range calculator'!$E$19,(H41+'range calculator'!$E$18)/2*(H41-'range calculator'!$E$18)/('range calculator'!$E$19-'range calculator'!$E$18)+H41*(1-(H41-'range calculator'!$E$18)/('range calculator'!$E$19-'range calculator'!$E$18)),'range calculator'!$D$20) -> -18506.305 | L41: -- | M41: =IF(J41<='range calculator'!$E$19,(J41+'range calculator'!$E$18)/2*(J41-'range calculator'!$E$18)/('range calculator'!$E$19-'range calculator'!$E$18)+J41*(1-(J41-'range calculator'!$E$18)/('range calculator'!$E$19-'range calculator'!$E$18)),'range calculator'!$D$20) -> -18691.723 | N41: =IF('range calculator'!$D$13="Yes",E41*0.85*K41+G41*0.15*M41, E41*K41) -> -12810385 | O41: =N41/C41 -> -4744587
A42: Bishop | B42: Angel Ray | C42: 0.81 | D42: =IF('range calculator'!$B$34="Yes",'range calculator'!$D$34,240) -> 240 | E42: =D42*IF('range calculator'!$D$16="Yes",1.5,1) -> 240 | F42: -- | G42: =(D42+140)*IF('range calculator'!$D$16="Yes",1.5,1) -> 380 | H42: =$B$1/(E42) -> 833.32917 | I42: -- | J42: =$B$1/(G42) -> 526.31316 | K42: =IF(H42<='range calculator'!$E$19,(H42+'range calculator'!$E$18)/2*(H42-'range calculator'!$E$18)/('range calculator'!$E$19-'range calculator'!$E$18)+H42*(1-(H42-'range calculator'!$E$18)/('range calculator'!$E$19-'range calculator'!$E$18)),'range calculator'!$D$20) -> -16612.203 | L42: -- | M42: =IF(J42<='range calculator'!$E$19,(J42+'range calculator'!$E$18)/2*(J42-'range calculator'!$E$18)/('range calculator'!$E$19-'range calculator'!$E$18)+J42*(1-(J42-'range calculator'!$E$18)/('range calculator'!$E$19-'range calculator'!$E$18)),'range calculator'!$D$20) -> -17693.281 | N42: =IF('range calculator'!$D$13="Yes",E42*0.85*K42+G42*0.15*M42, E42*K42) -> -4397406.4 | O42: =N42/C42 -> -5428896.8
A43: Shad | B43: Boomerang Step | C43: 0.69 | D43: =IF('range calculator'!$B$34="Yes",'range calculator'!$D$34,600) -> 600 | E43: =D43*IF('range calculator'!$D$16="Yes",1.5,1) -> 600 | F43: -- | G43: =(D43+140)*IF('range calculator'!$D$16="Yes",1.5,1) -> 740 | H43: =$B$1/(E43%) -> 33333.167 | I43: -- | J43: =$B$1/(G43%) -> 27026.892 | K43: =IF(H43<='range calculator'!$E$19,(H43+'range calculator'!$E$18)/2*(H43-'range calculator'!$E$18)/('range calculator'!$E$19-'range calculator'!$E$18)+H43*(1-(H43-'range calculator'!$E$18)/('range calculator'!$E$19-'range calculator'!$E$18)),'range calculator'!$D$20) -> 17629 | L43: -- | M43: =IF(J43<='range calculator'!$E$19,(J43+'range calculator'!$E$18)/2*(J43-'range calculator'!$E$18)/('range calculator'!$E$19-'range calculator'!$E$18)+J43*(1-(J43-'range calculator'!$E$18)/('range calculator'!$E$19-'range calculator'!$E$18)),'range calculator'!$D$20) -> 17629 | N43: =IF('range calculator'!$D$13="Yes",E43%*0.85*K43+G43%*0.15*M43, E43%*K43)*2 -> 218952.18 | O43: =N43/C43 -> 317322
A44: Shad | B44: Assassinate 30 | C44: 1.62 | D44: =IF('range calculator'!$B$34="Yes",'range calculator'!$D$34,950) -> 950 | E44: =D44*IF('range calculator'!$D$16="Yes",1.5,1) -> 950 | G44: =(D44+140)*IF('range calculator'!$D$16="Yes",1.5,1) -> 1090 | H44: =$B$1/(E44%) -> 21052.526 | I44: -- | J44: =$B$1/(G44%) -> 18348.532 | K44: =IF(H44<='range calculator'!$E$19,(H44+'range calculator'!$E$18)/2*(H44-'range calculator'!$E$18)/('range calculator'!$E$19-'range calculator'!$E$18)+H44*(1-(H44-'range calculator'!$E$18)/('range calculator'!$E$19-'range calculator'!$E$18)),'range calculator'!$D$20) -> 17629 | L44: -- | M44: =IF(J44<='range calculator'!$E$19,(J44+'range calculator'!$E$18)/2*(J44-'range calculator'!$E$18)/('range calculator'!$E$19-'range calculator'!$E$18)+J44*(1-(J44-'range calculator'!$E$18)/('range calculator'!$E$19-'range calculator'!$E$18)),'range calculator'!$D$20) -> 17241.373 | N44: =IF('range calculator'!$D$13="Yes",E44%*0.85*K44+G44%*0.15*M44, E44%*K44)*3 -> 511631.46 | O44: =N44/C44 -> 315821.89
A45: Shad | B45: Assassinate 20 | C45: 1.62 | D45: =IF('range calculator'!$B$34="Yes",'range calculator'!$D$34,500) -> 500 | E45: =D45*IF('range calculator'!$D$16="Yes",1.5,1) -> 500 | G45: =(D45+140)*IF('range calculator'!$D$16="Yes",1.5,1) -> 640 | H45: =$B$1/(E45%) -> 39999.8 | I45: -- | J45: =$B$1/(G45%) -> 31249.844 | K45: =IF(H45<='range calculator'!$E$19,(H45+'range calculator'!$E$18)/2*(H45-'range calculator'!$E$18)/('range calculator'!$E$19-'range calculator'!$E$18)+H45*(1-(H45-'range calculator'!$E$18)/('range calculator'!$E$19-'range calculator'!$E$18)),'range calculator'!$D$20) -> 17629 | L45: -- | M45: =IF(J45<='range calculator'!$E$19,(J45+'range calculator'!$E$18)/2*(J45-'range calculator'!$E$18)/('range calculator'!$E$19-'range calculator'!$E$18)+J45*(1-(J45-'range calculator'!$E$18)/('range calculator'!$E$19-'range calculator'!$E$18)),'range calculator'!$D$20) -> 17629 | N45: =IF('range calculator'!$D$13="Yes",E45%*0.85*K45+G45%*0.15*M45, E45%*K45)*3 -> 275541.27 | O45: =N45/C45 -> 170087.2
...

Sheet summons
A1: Job | B1: Skill name | C1: Time before attack /s | D1: Avg damage | E1: dps | F1: notes
B2: None | C2: -- | D2: -- | E2: 0
A3: BM | B3: Phoenix | C3: 3.03 | D3: =('range calculator'!$I$31*4.25+'range calculator'!$H$31*2)*550/200 -> 8480.3125 | E3: =D3/C3 -> 2798.783 | I3: Phoenix/Frostprey/Octopus/Gaviota (credit to Sybaris/KaidaTan):
A4: MM | B4: Frostprey | C4: 3.03 | D4: =('range calculator'!$I$31*4.25+'range calculator'!$H$31*2)*500/200 -> 7709.375 | E4: =D4/C4 -> 2544.3482 | I4: MAX = (DEX * 2.5 + STR) * Attack Rate / 100
A5: AM | B5: Ifrit | C5: 3.03 | D5: =300*'range calculator'!$D$20/1.4/1.25 -> 3022114.3 | E5: =D5/C5 -> 997397.45 | I5: MIN = (DEX * 2.5 * 0.7 + STR) * Attack Rate / 100
A6: AM | B6: Elquines | C6: 3.03 | D6: =270*'range calculator'!$D$20/1.4/1.25 -> 2719902.9 | E6: =D6/C6 -> 897657.71 | I6: Ignores defense
A7: Bishop | B7: Bahamut | C7: 3.03 | D7: =230*'range calculator'!$D$20 -> 4054670 | E7: =D7/C7 -> 1338174.9 | I7: AVG= (4.25DEX + 2STR ) * Attack Rate / 200

Sheet maple warrior
A1: Lv | B1: Multiplier
A2: 0 | B2: 1
A3: 1 | B3: 1.01
A4: 2 | B4: 1.01
A5: 3 | B5: 1.02
A6: 4 | B6: 1.02
A7: 5 | B7: 1.03
A8: 6 | B8: 1.03
A9: 7 | B9: 1.04
A10: 8 | B10: 1.04
A11: 9 | B11: 1.05
A12: 10 | B12: 1.05
A13: 11 | B13: 1.06
... A32: 30 | B32: 1.15

Sheet Weapons
B1: Hero | C1: Pally | D1: BM | E1: MM | F1: DrK | G1: NL | H1: Sair | I1: Bucc | J1: Shad | K1: Archmage | L1: Bishop
B2: 1H Sword | C2: 1H Sword
B3: 2H Sword | C3: 2H Sword
B4: 1H Axe | C4: 1H BW
B5: 2H Axe | C5: 2H BW
E7: Slash Multipliers | F7: Stab | H7: One Handed Axe/BW/Wand/Staff (Swinging)
B8: Dynamic list | D8: 1H Axe | E8: 4.4 | F8: 3.2 | H8: Primary: STR * 4.4
B9: =IFERROR(__xludf.DUMMYFUNCTION("SORT(FILTER(B2:Z5,'range calculator'!$D$5=$B$1:Z1),2,TRUE)"),"") | D9: 2H Axe | E9: 4.8 | F9: 3.4 | H9: Secondary: DEX
D10: 1H BW | E10: 4.4 | F10: 3.2
D11: 2H BW | E11: 4.8 | F11: 3.4 | H11: One Handed Axe/BW/Wand/Staff (Stabbing)
D12: 1H Sword | E12: 4 | F12: 4 | H12: Primary: STR * 3.2
D13: 2H Sword | E13: 4.6 | F13: 4.6 | H13: Secondary: DEX
H15: Two Handed Sword
H16: Primary: STR * 4.6
H17: Secondary: DEX
H19: Two Handed Axe/BW (Swinging)
H20: Primary: STR * 4.8
H21: Secondary: DEX
H23: Two Handed Axe/BW (Stabbing)
H24: Primary: STR * 3.4
H25: Secondary: DEX

Sheet Attack Speed
A1: 1 | B1: 2 | C1: 3 | D1: 4 | E1: 5 | F1: 6
B2: Battleship Cannon | C2: Strafe/Snipe | D2: Crusher | E2: Brandish | F2: Blast
A3: 2 | B3: 0.6 | C3: 0.6 | D3: 0.81 | E3: 0.63 | F3: 0.63
A4: 3 | B4: 0.63 | C4: 0.69 | D4: 0.87 | E4: 0.69 | F4: 0.69
A5: 4 | B5: 0.69 | C5: 0.72 | D5: 0.93 | E5: 0.75 | F5: 0.75
A6: 5 | B6: 0.75 | C6: 0.78 | D6: 0.99 | E6: 0.81 | F6: 0.81
A7: 6 | B7: 0.78 | C7: 0.87 | D7: 1.05 | E7: 0.84 | F7: 0.84
B8: =VLOOKUP(3,'Attack Speed'!A2:F7,2,true) -> 0.63

Sheet templates (old)
B1: Mid tier | H1: Mid-high tier | N1: High tier
A2: NL | E2: 16 | F2: 75 | K2: 18 | L2: 85 | Q2: 20 | R2: 95
B5: 15 | C5: 29 | D5: 15 | E5: 17 | H5: 15 | I5: 38 | J5: 15 | K5: 17 | N5: 15 | O5: 47 | P5: 15 | Q5: 17
C6: 7 | E6: 20 | I6: 7 | K6: 26 | O6: 7 | Q6: 32
C7: 16 | E7: 9 | I7: 22 | K7: 9 | O7: 28 | Q7: 9
F8: 11 | L8: 15 | R8: 19
F9: 9 | L9: 13 | R9: 17
F10: 15 | L10: 17 | R10: 22
C13: 10 | H13: 2 | I13: 12 | J13: 2 | K13: 2 | N13: 2 | O13: 15 | P13: 2 | Q13: 2
C14: 1 | I14: 11 | O14: 13
C15: 9 | I15: 3 | Q15: 8
B16: 22 | C16: 22 | D16: 22 | E16: 22 | H16: 22 | I16: 22 | J16: 22 | K16: 22 | N16: 22 | O16: 28 | P16: 22 | Q16: 28
B18: 2 | C18: 2 | D18: 2 | E18: 2 | H18: 2 | I18: 2 | J18: 2 | K18: 2 | N18: 2 | O18: 2 | P18: 2 | Q18: 2
B19: 1 | C19: 1 | D19: 1 | E19: 1 | H19: 1 | I19: 1 | J19: 1 | K19: 1 | N19: 1 | O19: 1 | P19: 1 | Q19: 1
B20: 1 | C20: 1 | D20: 1 | E20: 1 | H20: 1 | I20: 1 | J20: 1 | K20: 1 | N20: 1 | O20: 1 | P20: 1 | Q20: 1
B21: 3 | C21: 3 | D21: 3 | E21: 3 | F21: 1 | H21: 3 | I21: 3 | J21: 3 | K21: 3 | L21: 1 | N21: 3 | O21: 3 | P21: 3 | Q21: 3 | R21: 1
B22: 3 | C22: 3 | D22: 3 | E22: 3 | H22: 3 | I22: 3 | J22: 3 | K22: 3 | N22: 3 | O22: 3 | P22: 3 | Q22: 3
B24: 4 | C24: 42 | D24: 4 | E24: 780 | H24: 4 | I24: 23 | J24: 4 | K24: 869 | N24: 4 | O24: 4 | P24: 4 | Q24: 943
A27: Shad | E27: 9 | F27: 125 | K27: 15 | L27: 135 | Q27: 21 | R27: 145
B28: 6 | F28: 31 | H28: 15 | L28: 37 | N28: 21 | R28: 43
B30: 17 | C30: 29 | D30: 15 | E30: 17 | H30: 17 | I30: 29 | J30: 15 | K30: 17 | N30: 17 | O30: 47 | P30: 15 | Q30: 17
C31: 7 | E31: 20 | I31: 7 | K31: 26 | O31: 7 | Q31: 32
C32: 16 | E32: 9 | I32: 22 | K32: 9 | O32: 28 | Q32: 9
F33: 11 | L33: 11 | R33: 19
F34: 9 | L34: 9 | R34: 17
F35: 15 | L35: 15 | R35: 22
C38: 10 | I38: 14 | N38: 2 | O38: 15 | P38: 2 | Q38: 2
C39: 1 | I39: 3 | Q39: 8
C40: 9 | I40: 9 | Q40: 8
B41: 22 | C41: 22 | D41: 22 | E41: 22 | H41: 22 | I41: 22 | J41: 22 | K41: 22 | N41: 28 | O41: 28 | P41: 23 | Q41: 28
B43: 2 | C43: 2 | D43: 2 | E43: 2 | H43: 2 | I43: 2 | J43: 2 | K43: 2 | N43: 2 | O43: 2 | P43: 2 | Q43: 2
B44: 1 | C44: 1 | D44: 1 | E44: 1 | H44: 1 | I44: 1 | J44: 1 | K44: 1 | N44: 1 | O44: 1 | P44: 1 | Q44: 1
B45: 1 | C45: 1 | D45: 1 | E45: 1 | H45: 1 | I45: 1 | J45: 1 | K45: 1 | N45: 1 | O45: 1 | P45: 1 | Q45: 1
B46: 3 | C46: 3 | D46: 3 | E46: 3 | F46: 1 | H46: 3 | I46: 3 | J46: 3 | K46: 3 | L46: 1 | N46: 3 | O46: 3 | P46: 3 | Q46: 3 | R46: 1
B47: 3 | C47: 3 | D47: 3 | E47: 3 | H47: 3 | I47: 3 | J47: 3 | K47: 3 | N47: 3 | O47: 3 | P47: 3 | Q47: 3
B49: 26 | C49: 46 | D49: 4 | E49: 765 | H49: 10 | I49: 31 | J49: 4 | K49: 860 | N49: 4 | O49: 14 | P49: 4 | Q49: 933
B51: Mid tier | H51: Mid-high tier | N51: High tier
A52: Hero/Pally | B52: 9 | F52: 130 | H52: 15 | L52: 140 | N52: 21 | R52: 150
B55: 17 | C55: 29 | D55: 15 | E55: 15 | H55: 3 | I55: 3 | J55: 3 | K55: 3 | L55: 4 | N55: 6 | O55: 6 | P55: 6 | Q55: 6 | R55: 6
B56: 31 | C56: 9 | H56: 46 | I56: 9 | N56: 61 | O56: 9
...
